Workbook

Sheet README
A1: Ask Ekiti — Source Inventory & Evaluation Workbook (v0.3)
A2: Owner: Member 3, AI & Data Lead | Related issue: #3 | Status: revised draft, not approved, not merged
A3: This workbook is the companion source of truth to Ask_Ekiti_KB_Spec.md. Formulas check each row against the spec (A3–A9).
A5: Sheets
A6: Source Inventory: one row per source. Record stage 'Identified' = the source is pinned down (title, publisher, exact location) and ready for review. 'Source needed' = still to be found.
A7: Summary: counts and launch blockers. First Documents (Language column: KB documents are written in English; Yoruba answers are generated from verified English content under spec A9.9): planned KB files, each linked to its Source IDs with live status. Eval Starter Set: seed questions, each mapped to a spec rule. Lists: topic-to-folder map.
A9: Source Inventory columns (spec A4)
A10: Source ID (SRC-###) · Record stage · Priority (P1 launch, P2 if time, P3 after) · Topic / KB category · Information supported · Source title · Source type · Primary / Secondary / Oral · Publisher / owner.
A11: URL or document location + Location type (Original / Hosted copy / Offline) + Host of copy: if the link is a copy on another site, record both the original publisher and the host.
A12: Publication date of the source: when the source itself was published (YYYY-MM-DD, YYYY-MM or YYYY). Write 'Not stated' if the page shows no date. This is not the verification date.
A13: Tier: A primary/official, B academic/institutional, C news/secondary, D oral/community. Rule: A = Primary, B and C = Secondary, D = Oral. The check flags mismatches.
A14: Status: Not started, In progress, Needs review, Verified, Conflict, Blocked.
... A33: • Verification Lead: Member 8, Victor Ogunyemi. Senior reviewer: Member 1, Faith Ogunlade. Yoruba reviewer: not yet assigned.

Sheet Source Inventory
A1: Source ID | B1: Record stage | C1: Priority | D1: Topic / KB category | E1: Information this source supports | F1: Source title | G1: Source type | H1: Primary / Secondary / Oral | I1: Publisher / owner | J1: URL or document location | K1: Location type | L1: Host of copy (if a copy) | M1: Publication date of the source | N1: Tier | O1: Owner team | P1: Status | Q1: Verification date | R1: Verified by | S1: Corroboration (Tier C: Source IDs or EXCEPTION) | T1: Verification note (reasoning) | U1: Conflicts / notes | V1: Planned KB / research file | W1: Planned docs using this source | X1: Rule check | Y1: (helper) missing fields
A2: SRC-001 | B2: Identified | C2: P1 | D2: history | E2: Ekiti State creation date (1 October 1996) as stated by the state government | F2: Ekiti At 25: Governor Fayemi pays Tribute to Founding Fathers, Ex-Governors Adebayo, Fayose, Oni, Others (1 Oct 2021) | G2: Government press release | H2: Primary (official) | I2: Government of Ekiti State | J2: https://www.ekitistate.gov.ng/archives/23334 | K2: Original | M2: 2021-10-01 | N2: A | O2: Research & History | P2: Not started | U2: Anniversary statement confirming creation on 1 October 1996. It is not the founding instrument, so SRC-002 is still needed. It names the early administrators and governors, so it is relevant to SRC-010. | V2: 01_History/state-creation-1996.md | W2: =COUNTIF('First Documents'!$G$2:$G$300,A2) | X2: =IF(A2="","",IF(LEFT(A2,4)<>"SRC-","Bad ID format",IF(COUNTIF($A$2:$A$300,A2)>1,"Duplicate ID",IF(NOT(OR(V2="",SUMPRODUCT((Lists!$A$2:$A$11=D2)*(LEFT(V2,LEN(Lists!$B$2:$B$11))=Lists!$B$2:$B$11))>0)),"Planned file is not in the folder for this topic",IF(AND(N2<>"",H2<>"",NOT(OR(AND(N2="A",H2="Primary (official)"),AND(OR(N2="B",N2="C"),H2="Secondary"),AND(N2="D",H2="Oral / community")))),"Tier/class mismatch",IF(AND(N2="D",C2<>"P3"),"Tier D is not allowed at launch (set P3)",IF(B2="Source needed",IF(C2="P1","Source needed (launch blocker)",IF(P2="Blocked","Deferred","Source needed")),IF(LEN(Y2)>0,"Incomplete: "&Y2,IF(ISNUMBER(SEARCH("wikipedia",J2)),"Wikipedia is not an accepted source",IF(AND(P2="Verified",OR(Q2="",R2="")),"Verified: add date and verifier",IF(AND(Q2<>"",Q2>TODAY()),"Future verification date",IF(AND(P2="Verified",N2="C",S2=""),"Tier C: add corroboration or EXCEPTION",IF(AND(P2="Verified",N2="D",T2=""),"Tier D: add Verification Lead note",IF(AND(P2="Conflict",U2=""),"Conflict needs a note",IF(W2=0,"Not linked to any planned document","OK"))))))))))))))) | Y2: =IF(A2="","",IF(B2="Source needed","",IF(D2="","topic; ","")&IF(F2="","title; ","")&IF(G2="","type; ","")&IF(H2="","primary/secondary; ","")&IF(I2="","publisher; ","")&IF(J2="","URL/location; ","")&IF(K2="","location type; ","")&IF(AND(K2="Hosted copy",L2=""),"host of copy; ","")&IF(M2="","publication date; ","")&IF(N2="","tier; ","")))
A3: SRC-002 | B3: Source needed | C3: P1 | D3: history | E3: Founding instrument or original announcement creating Ekiti State (1 Oct 1996) | G3: Federal decree / gazette / archive record | H3: Primary (official) | I3: Federal Republic of Nigeria (issuing body to confirm) | N3: A | O3: Research & History | P3: Not started | U3: To locate: the decree, gazette or official announcement of 1 Oct 1996 (national archives, gazette collections). Until found, the creation date rests on SRC-001 alone. | V3: 01_History/state-creation-1996.md | W3: =COUNTIF('First Documents'!$G$2:$G$300,A3) | X3: =IF(A3="","",IF(LEFT(A3,4)<>"SRC-","Bad ID format",IF(COUNTIF($A$2:$A$300,A3)>1,"Duplicate ID",IF(NOT(OR(V3="",SUMPRODUCT((Lists!$A$2:$A$11=D3)*(LEFT(V3,LEN(Lists!$B$2:$B$11))=Lists!$B$2:$B$11))>0)),"Planned file is not in the folder for this topic",IF(AND(N3<>"",H3<>"",NOT(OR(AND(N3="A",H3="Primary (official)"),AND(OR(N3="B",N3="C"),H3="Secondary"),AND(N3="D",H3="Oral / community")))),"Tier/class mismatch",IF(AND(N3="D",C3<>"P3"),"Tier D is not allowed at launch (set P3)",IF(B3="Source needed",IF(C3="P1","Source needed (launch blocker)",IF(P3="Blocked","Deferred","Source needed")),IF(LEN(Y3)>0,"Incomplete: "&Y3,IF(ISNUMBER(SEARCH("wikipedia",J3)),"Wikipedia is not an accepted source",IF(AND(P3="Verified",OR(Q3="",R3="")),"Verified: add date and verifier",IF(AND(Q3<>"",Q3>TODAY()),"Future verification date",IF(AND(P3="Verified",N3="C",S3=""),"Tier C: add corroboration or EXCEPTION",IF(AND(P3="Verified",N3="D",T3=""),"Tier D: add Verification Lead note",IF(AND(P3="Conflict",U3=""),"Conflict needs a note",IF(W3=0,"Not linked to any planned document","OK"))))))))))))))) | Y3: =IF(A3="","",IF(B3="Source needed","",IF(D3="","topic; ","")&IF(F3="","title; ","")&IF(G3="","type; ","")&IF(H3="","primary/secondary; ","")&IF(I3="","publisher; ","")&IF(J3="","URL/location; ","")&IF(K3="","location type; ","")&IF(AND(K3="Hosted copy",L3=""),"host of copy; ","")&IF(M3="","publication date; ","")&IF(N3="","tier; ","")))
A4: SRC-003 | B4: Identified | C4: P1 | D4: lgas | E4: State profile: 16 LGAs, headquarters, land area, earlier census figures | F4: About Ekiti (state government page) | G4: Government website page | H4: Primary (official) | I4: Government of Ekiti State | J4: https://www.ekitistate.gov.ng/?p=444 | K4: Original | M4: Not stated | N4: A | O4: Geospatial | P4: Needs review | U4: Its 2006 state total (2,384,212) differs from other sources: see SRC-008 and SRC-009. Compare its LGA table line by line with the Constitution (SRC-004). Check the full page: the excerpt reviewed was incomplete. | V4: 02_LGAs/<lga-slug>.md | W4: =COUNTIF('First Documents'!$G$2:$G$300,A4) | X4: =IF(A4="","",IF(LEFT(A4,4)<>"SRC-","Bad ID format",IF(COUNTIF($A$2:$A$300,A4)>1,"Duplicate ID",IF(NOT(OR(V4="",SUMPRODUCT((Lists!$A$2:$A$11=D4)*(LEFT(V4,LEN(Lists!$B$2:$B$11))=Lists!$B$2:$B$11))>0)),"Planned file is not in the folder for this topic",IF(AND(N4<>"",H4<>"",NOT(OR(AND(N4="A",H4="Primary (official)"),AND(OR(N4="B",N4="C"),H4="Secondary"),AND(N4="D",H4="Oral / community")))),"Tier/class mismatch",IF(AND(N4="D",C4<>"P3"),"Tier D is not allowed at launch (set P3)",IF(B4="Source needed",IF(C4="P1","Source needed (launch blocker)",IF(P4="Blocked","Deferred","Source needed")),IF(LEN(Y4)>0,"Incomplete: "&Y4,IF(ISNUMBER(SEARCH("wikipedia",J4)),"Wikipedia is not an accepted source",IF(AND(P4="Verified",OR(Q4="",R4="")),"Verified: add date and verifier",IF(AND(Q4<>"",Q4>TODAY()),"Future verification date",IF(AND(P4="Verified",N4="C",S4=""),"Tier C: add corroboration or EXCEPTION",IF(AND(P4="Verified",N4="D",T4=""),"Tier D: add Verification Lead note",IF(AND(P4="Conflict",U4=""),"Conflict needs a note",IF(W4=0,"Not linked to any planned document","OK"))))))))))))))) | Y4: =IF(A4="","",IF(B4="Source needed","",IF(D4="","topic; ","")&IF(F4="","title; ","")&IF(G4="","type; ","")&IF(H4="","primary/secondary; ","")&IF(I4="","publisher; ","")&IF(J4="","URL/location; ","")&IF(K4="","location type; ","")&IF(AND(K4="Hosted copy",L4=""),"host of copy; ","")&IF(M4="","publication date; ","")&IF(N4="","tier; ","")))
A5: SRC-004 | B5: Identified | C5: P1 | D5: lgas | E5: Names of the 16 LGAs (legal list) | F5: Constitution of the Federal Republic of Nigeria 1999, First Schedule Part I (as amended) | G5: Legal instrument | H5: Primary (official) | I5: Federal Republic of Nigeria | J5: https://www.wipo.int/wipolex/en/text/218190 | K5: Hosted copy | L5: WIPO Lex (wipo.int) | M5: 1999 | N5: A | O5: Geospatial | P5: Not started | U5: The link is a copy hosted by WIPO Lex and appears to be the original 1999 text. The Constitution has been amended, so confirm the current version from an official publication. Another site hosting the schedules is not official. | V5: 02_LGAs/<lga-slug>.md | W5: =COUNTIF('First Documents'!$G$2:$G$300,A5) | X5: =IF(A5="","",IF(LEFT(A5,4)<>"SRC-","Bad ID format",IF(COUNTIF($A$2:$A$300,A5)>1,"Duplicate ID",IF(NOT(OR(V5="",SUMPRODUCT((Lists!$A$2:$A$11=D5)*(LEFT(V5,LEN(Lists!$B$2:$B$11))=Lists!$B$2:$B$11))>0)),"Planned file is not in the folder for this topic",IF(AND(N5<>"",H5<>"",NOT(OR(AND(N5="A",H5="Primary (official)"),AND(OR(N5="B",N5="C"),H5="Secondary"),AND(N5="D",H5="Oral / community")))),"Tier/class mismatch",IF(AND(N5="D",C5<>"P3"),"Tier D is not allowed at launch (set P3)",IF(B5="Source needed",IF(C5="P1","Source needed (launch blocker)",IF(P5="Blocked","Deferred","Source needed")),IF(LEN(Y5)>0,"Incomplete: "&Y5,IF(ISNUMBER(SEARCH("wikipedia",J5)),"Wikipedia is not an accepted source",IF(AND(P5="Verified",OR(Q5="",R5="")),"Verified: add date and verifier",IF(AND(Q5<>"",Q5>TODAY()),"Future verification date",IF(AND(P5="Verified",N5="C",S5=""),"Tier C: add corroboration or EXCEPTION",IF(AND(P5="Verified",N5="D",T5=""),"Tier D: add Verification Lead note",IF(AND(P5="Conflict",U5=""),"Conflict needs a note",IF(W5=0,"Not linked to any planned document","OK"))))))))))))))) | Y5: =IF(A5="","",IF(B5="Source needed","",IF(D5="","topic; ","")&IF(F5="","title; ","")&IF(G5="","type; ","")&IF(H5="","primary/secondary; ","")&IF(I5="","publisher; ","")&IF(J5="","URL/location; ","")&IF(K5="","location type; ","")&IF(AND(K5="Hosted copy",L5=""),"host of copy; ","")&IF(M5="","publication date; ","")&IF(N5="","tier; ","")))
A6: SRC-005 | B6: Identified | C6: P1 | D6: lgas | E6: LGA descriptions and headquarters from the state's own LGA pages | F6: Ekiti State Government: About Ekiti > Local Government (one page per LGA) | G6: Government website page | H6: Primary (official) | I6: Government of Ekiti State | J6: https://www.ekitistate.gov.ng/about-ekiti/local-government/ilejemeje | K6: Original | M6: Not stated | N6: A | O6: Geospatial | P6: Needs review | U6: Possible error: the page at the 'ilejemeje' address describes Ekiti South West LG with headquarters Ilawe Ekiti. Check whether the page is mislabelled before copying anything. Register each LGA page as its own row when used. | V6: 02_LGAs/<lga-slug>.md | W6: =COUNTIF('First Documents'!$G$2:$G$300,A6) | X6: =IF(A6="","",IF(LEFT(A6,4)<>"SRC-","Bad ID format",IF(COUNTIF($A$2:$A$300,A6)>1,"Duplicate ID",IF(NOT(OR(V6="",SUMPRODUCT((Lists!$A$2:$A$11=D6)*(LEFT(V6,LEN(Lists!$B$2:$B$11))=Lists!$B$2:$B$11))>0)),"Planned file is not in the folder for this topic",IF(AND(N6<>"",H6<>"",NOT(OR(AND(N6="A",H6="Primary (official)"),AND(OR(N6="B",N6="C"),H6="Secondary"),AND(N6="D",H6="Oral / community")))),"Tier/class mismatch",IF(AND(N6="D",C6<>"P3"),"Tier D is not allowed at launch (set P3)",IF(B6="Source needed",IF(C6="P1","Source needed (launch blocker)",IF(P6="Blocked","Deferred","Source needed")),IF(LEN(Y6)>0,"Incomplete: "&Y6,IF(ISNUMBER(SEARCH("wikipedia",J6)),"Wikipedia is not an accepted source",IF(AND(P6="Verified",OR(Q6="",R6="")),"Verified: add date and verifier",IF(AND(Q6<>"",Q6>TODAY()),"Future verification date",IF(AND(P6="Verified",N6="C",S6=""),"Tier C: add corroboration or EXCEPTION",IF(AND(P6="Verified",N6="D",T6=""),"Tier D: add Verification Lead note",IF(AND(P6="Conflict",U6=""),"Conflict needs a note",IF(W6=0,"Not linked to any planned document","OK"))))))))))))))) | Y6: =IF(A6="","",IF(B6="Source needed","",IF(D6="","topic; ","")&IF(F6="","title; ","")&IF(G6="","type; ","")&IF(H6="","primary/secondary; ","")&IF(I6="","publisher; ","")&IF(J6="","URL/location; ","")&IF(K6="","location type; ","")&IF(AND(K6="Hosted copy",L6=""),"host of copy; ","")&IF(M6="","publication date; ","")&IF(N6="","tier; ","")))
A7: SRC-006 | B7: Identified | C7: P1 | D7: lgas | E7: Distinguish the 16 constitutional LGAs from proposed new LCDAs | F7: Creation of Local Government Bill, 2021 (state government statement) | G7: Government statement | H7: Primary (official) | I7: Government of Ekiti State | J7: https://www.ekitistate.gov.ng/?p=23151 | K7: Original | M7: Not stated | N7: A | O7: Geospatial | P7: Not started | U7: States that the 16 LGAs are those in the Constitution and describes 19 proposed LCDAs that operate as LCDAs unless nationally recognised. Keep LGAs and LCDAs separate. Check the current status of the proposal. | V7: 02_LGAs/<lga-slug>.md | W7: =COUNTIF('First Documents'!$G$2:$G$300,A7) | X7: =IF(A7="","",IF(LEFT(A7,4)<>"SRC-","Bad ID format",IF(COUNTIF($A$2:$A$300,A7)>1,"Duplicate ID",IF(NOT(OR(V7="",SUMPRODUCT((Lists!$A$2:$A$11=D7)*(LEFT(V7,LEN(Lists!$B$2:$B$11))=Lists!$B$2:$B$11))>0)),"Planned file is not in the folder for this topic",IF(AND(N7<>"",H7<>"",NOT(OR(AND(N7="A",H7="Primary (official)"),AND(OR(N7="B",N7="C"),H7="Secondary"),AND(N7="D",H7="Oral / community")))),"Tier/class mismatch",IF(AND(N7="D",C7<>"P3"),"Tier D is not allowed at launch (set P3)",IF(B7="Source needed",IF(C7="P1","Source needed (launch blocker)",IF(P7="Blocked","Deferred","Source needed")),IF(LEN(Y7)>0,"Incomplete: "&Y7,IF(ISNUMBER(SEARCH("wikipedia",J7)),"Wikipedia is not an accepted source",IF(AND(P7="Verified",OR(Q7="",R7="")),"Verified: add date and verifier",IF(AND(Q7<>"",Q7>TODAY()),"Future verification date",IF(AND(P7="Verified",N7="C",S7=""),"Tier C: add corroboration or EXCEPTION",IF(AND(P7="Verified",N7="D",T7=""),"Tier D: add Verification Lead note",IF(AND(P7="Conflict",U7=""),"Conflict needs a note",IF(W7=0,"Not linked to any planned document","OK"))))))))))))))) | Y7: =IF(A7="","",IF(B7="Source needed","",IF(D7="","topic; ","")&IF(F7="","title; ","")&IF(G7="","type; ","")&IF(H7="","primary/secondary; ","")&IF(I7="","publisher; ","")&IF(J7="","URL/location; ","")&IF(K7="","location type; ","")&IF(AND(K7="Hosted copy",L7=""),"host of copy; ","")&IF(M7="","publication date; ","")&IF(N7="","tier; ","")))
A8: SRC-007 | B8: Source needed | C8: P1 | D8: lgas | E8: LGA and place coordinates for the map | G8: Geospatial dataset | N8: B | O8: Geospatial | P8: Not started | U8: Candidates to assess: the state Surveyor-General, GRID3 Nigeria, OpenStreetMap (check licence). Record the source of every coordinate. | V8: 02_LGAs/<lga-slug>.md | W8: =COUNTIF('First Documents'!$G$2:$G$300,A8) | X8: =IF(A8="","",IF(LEFT(A8,4)<>"SRC-","Bad ID format",IF(COUNTIF($A$2:$A$300,A8)>1,"Duplicate ID",IF(NOT(OR(V8="",SUMPRODUCT((Lists!$A$2:$A$11=D8)*(LEFT(V8,LEN(Lists!$B$2:$B$11))=Lists!$B$2:$B$11))>0)),"Planned file is not in the folder for this topic",IF(AND(N8<>"",H8<>"",NOT(OR(AND(N8="A",H8="Primary (official)"),AND(OR(N8="B",N8="C"),H8="Secondary"),AND(N8="D",H8="Oral / community")))),"Tier/class mismatch",IF(AND(N8="D",C8<>"P3"),"Tier D is not allowed at launch (set P3)",IF(B8="Source needed",IF(C8="P1","Source needed (launch blocker)",IF(P8="Blocked","Deferred","Source needed")),IF(LEN(Y8)>0,"Incomplete: "&Y8,IF(ISNUMBER(SEARCH("wikipedia",J8)),"Wikipedia is not an accepted source",IF(AND(P8="Verified",OR(Q8="",R8="")),"Verified: add date and verifier",IF(AND(Q8<>"",Q8>TODAY()),"Future verification date",IF(AND(P8="Verified",N8="C",S8=""),"Tier C: add corroboration or EXCEPTION",IF(AND(P8="Verified",N8="D",T8=""),"Tier D: add Verification Lead note",IF(AND(P8="Conflict",U8=""),"Conflict needs a note",IF(W8=0,"Not linked to any planned document","OK"))))))))))))))) | Y8: =IF(A8="","",IF(B8="Source needed","",IF(D8="","topic; ","")&IF(F8="","title; ","")&IF(G8="","type; ","")&IF(H8="","primary/secondary; ","")&IF(I8="","publisher; ","")&IF(J8="","URL/location; ","")&IF(K8="","location type; ","")&IF(AND(K8="Hosted copy",L8=""),"host of copy; ","")&IF(M8="","publication date; ","")&IF(N8="","tier; ","")))
A9: SRC-008 | B9: Identified | C9: P1 | D9: statistics | E9: 2006 census population by state and LGA | F9: 2006 Population and Housing Census, Priority Table Volume III: Population Distribution by Sex, State, LGA & Senatorial District (April 2010) | G9: Statistical publication | H9: Primary (official) | I9: National Population Commission, Abuja | J9: https://datacatalog.ihsn.org//catalog/3340/download/48521 | K9: Hosted copy | L9: IHSN Survey Catalog (datacatalog.ihsn.org) | M9: 2010-04 | N9: A | O9: AI & Data | P9: Conflict | U9: CONFLICT: 2006 figures for Ekiti differ between sources. The State Government page (SRC-003) gives 2,384,212. A secondary compilation of NPC data gives 2,398,957. Wikipedia shows a third figure (not an accepted source). Open this table and the final-results gazette (SRC-009), then record which figure is correct and why. No figure to be used before then. | V9: 09_Statistics/population-2006-census.md | W9: =COUNTIF('First Documents'!$G$2:$G$300,A9) | X9: =IF(A9="","",IF(LEFT(A9,4)<>"SRC-","Bad ID format",IF(COUNTIF($A$2:$A$300,A9)>1,"Duplicate ID",IF(NOT(OR(V9="",SUMPRODUCT((Lists!$A$2:$A$11=D9)*(LEFT(V9,LEN(Lists!$B$2:$B$11))=Lists!$B$2:$B$11))>0)),"Planned file is not in the folder for this topic",IF(AND(N9<>"",H9<>"",NOT(OR(AND(N9="A",H9="Primary (official)"),AND(OR(N9="B",N9="C"),H9="Secondary"),AND(N9="D",H9="Oral / community")))),"Tier/class mismatch",IF(AND(N9="D",C9<>"P3"),"Tier D is not allowed at launch (set P3)",IF(B9="Source needed",IF(C9="P1","Source needed (launch blocker)",IF(P9="Blocked","Deferred","Source needed")),IF(LEN(Y9)>0,"Incomplete: "&Y9,IF(ISNUMBER(SEARCH("wikipedia",J9)),"Wikipedia is not an accepted source",IF(AND(P9="Verified",OR(Q9="",R9="")),"Verified: add date and verifier",IF(AND(Q9<>"",Q9>TODAY()),"Future verification date",IF(AND(P9="Verified",N9="C",S9=""),"Tier C: add corroboration or EXCEPTION",IF(AND(P9="Verified",N9="D",T9=""),"Tier D: add Verification Lead note",IF(AND(P9="Conflict",U9=""),"Conflict needs a note",IF(W9=0,"Not linked to any planned document","OK"))))))))))))))) | Y9: =IF(A9="","",IF(B9="Source needed","",IF(D9="","topic; ","")&IF(F9="","title; ","")&IF(G9="","type; ","")&IF(H9="","primary/secondary; ","")&IF(I9="","publisher; ","")&IF(J9="","URL/location; ","")&IF(K9="","location type; ","")&IF(AND(K9="Hosted copy",L9=""),"host of copy; ","")&IF(M9="","publication date; ","")&IF(N9="","tier; ","")))
A10: SRC-009 | B10: Identified | C10: P1 | D10: statistics | E10: 2006 census final results (legal publication) | F10: Federal Government Gazette No. 2, Vol. 96, 2 February 2009: Census 2006 Final Results | G10: Gazette | H10: Primary (official) | I10: Federal Government of Nigeria | J10: https://archive.gazettes.africa/archive/ng/2009/ng-government-gazette-dated-2009-02-02-no-2.pdf | K10: Hosted copy | L10: Gazettes.Africa archive | M10: 2009-02-02 | N10: A | O10: AI & Data | P10: Not started | U10: Should decide the SRC-008 conflict if final and provisional figures were mixed up. The NPC preface mentions an earlier provisional-results gazette from 2007. Locate the official gazette copy if possible. | V10: 09_Statistics/population-2006-census.md | W10: =COUNTIF('First Documents'!$G$2:$G$300,A10) | X10: =IF(A10="","",IF(LEFT(A10,4)<>"SRC-","Bad ID format",IF(COUNTIF($A$2:$A$300,A10)>1,"Duplicate ID",IF(NOT(OR(V10="",SUMPRODUCT((Lists!$A$2:$A$11=D10)*(LEFT(V10,LEN(Lists!$B$2:$B$11))=Lists!$B$2:$B$11))>0)),"Planned file is not in the folder for this topic",IF(AND(N10<>"",H10<>"",NOT(OR(AND(N10="A",H10="Primary (official)"),AND(OR(N10="B",N10="C"),H10="Secondary"),AND(N10="D",H10="Oral / community")))),"Tier/class mismatch",IF(AND(N10="D",C10<>"P3"),"Tier D is not allowed at launch (set P3)",IF(B10="Source needed",IF(C10="P1","Source needed (launch blocker)",IF(P10="Blocked","Deferred","Source needed")),IF(LEN(Y10)>0,"Incomplete: "&Y10,IF(ISNUMBER(SEARCH("wikipedia",J10)),"Wikipedia is not an accepted source",IF(AND(P10="Verified",OR(Q10="",R10="")),"Verified: add date and verifier",IF(AND(Q10<>"",Q10>TODAY()),"Future verification date",IF(AND(P10="Verified",N10="C",S10=""),"Tier C: add corroboration or EXCEPTION",IF(AND(P10="Verified",N10="D",T10=""),"Tier D: add Verification Lead note",IF(AND(P10="Conflict",U10=""),"Conflict needs a note",IF(W10=0,"Not linked to any planned document","OK"))))))))))))))) | Y10: =IF(A10="","",IF(B10="Source needed","",IF(D10="","topic; ","")&IF(F10="","title; ","")&IF(G10="","type; ","")&IF(H10="","primary/secondary; ","")&IF(I10="","publisher; ","")&IF(J10="","URL/location; ","")&IF(K10="","location type; ","")&IF(AND(K10="Hosted copy",L10=""),"host of copy; ","")&IF(M10="","publication date; ","")&IF(N10="","tier; ","")))
A11: SRC-010 | B11: Identified | C11: P1 | D11: government | E11: Governors and administrators 1996–2026 with exact terms | F11: Past Governors (state government page) | G11: Government website page | H11: Primary (official) | I11: Government of Ekiti State | J11: https://ekitistate.gov.ng/?p=5305 | K11: Original | M11: Not stated | N11: A | O11: Research & History | P11: Conflict | U11: CONFLICT (names): the first administrator appears as 'Lt. Col. Mohammed Bawa' on this page, 'Col. Inua Bawa' / 'Inuwa Bawa' in state press items (SRC-001 and a 2013 item), and 'Colonel Mohammed Inua Bala' in a news listicle. The second administrator appears as both 'Atanda Yusuf' and 'Yusuf Atanda'. Standardise from an official appointment record. The excerpt reviewed stopped at 2006: check the full page for later periods, including the 2006 impeachment period and administrator. | V11: 01_History/government/governors-and-administrators.md | W11: =COUNTIF('First Documents'!$G$2:$G$300,A11) | X11: =IF(A11="","",IF(LEFT(A11,4)<>"SRC-","Bad ID format",IF(COUNTIF($A$2:$A$300,A11)>1,"Duplicate ID",IF(NOT(OR(V11="",SUMPRODUCT((Lists!$A$2:$A$11=D11)*(LEFT(V11,LEN(Lists!$B$2:$B$11))=Lists!$B$2:$B$11))>0)),"Planned file is not in the folder for this topic",IF(AND(N11<>"",H11<>"",NOT(OR(AND(N11="A",H11="Primary (official)"),AND(OR(N11="B",N11="C"),H11="Secondary"),AND(N11="D",H11="Oral / community")))),"Tier/class mismatch",IF(AND(N11="D",C11<>"P3"),"Tier D is not allowed at launch (set P3)",IF(B11="Source needed",IF(C11="P1","Source needed (launch blocker)",IF(P11="Blocked","Deferred","Source needed")),IF(LEN(Y11)>0,"Incomplete: "&Y11,IF(ISNUMBER(SEARCH("wikipedia",J11)),"Wikipedia is not an accepted source",IF(AND(P11="Verified",OR(Q11="",R11="")),"Verified: add date and verifier",IF(AND(Q11<>"",Q11>TODAY()),"Future verification date",IF(AND(P11="Verified",N11="C",S11=""),"Tier C: add corroboration or EXCEPTION",IF(AND(P11="Verified",N11="D",T11=""),"Tier D: add Verification Lead note",IF(AND(P11="Conflict",U11=""),"Conflict needs a note",IF(W11=0,"Not linked to any planned document","OK"))))))))))))))) | Y11: =IF(A11="","",IF(B11="Source needed","",IF(D11="","topic; ","")&IF(F11="","title; ","")&IF(G11="","type; ","")&IF(H11="","primary/secondary; ","")&IF(I11="","publisher; ","")&IF(J11="","URL/location; ","")&IF(K11="","location type; ","")&IF(AND(K11="Hosted copy",L11=""),"host of copy; ","")&IF(M11="","publication date; ","")&IF(N11="","tier; ","")))
A12: SRC-011 | B12: Source needed | C12: P1 | D12: tourism | E12: Tourism sites: name, LGA, description, coordinates | G12: Government listing | H12: Primary (official) | I12: State ministry or agency for culture and tourism (a 2013 state item names it 'Ministry of Culture, Arts and Tourism'; confirm current name) | N12: A | O12: Culture & Tourism | P12: Not started | U12: Leads, not sources: state-site feature articles and reprinted news (e.g. on Ikogosi Warm Spring) are not official listings. A federal survey report listing Ekiti sites was found at fmino.gov.ng/?p=8221; assess it. Aim for 20–30 places at launch. | V12: 04_Tourism/<site-slug>.md | W12: =COUNTIF('First Documents'!$G$2:$G$300,A12) | X12: =IF(A12="","",IF(LEFT(A12,4)<>"SRC-","Bad ID format",IF(COUNTIF($A$2:$A$300,A12)>1,"Duplicate ID",IF(NOT(OR(V12="",SUMPRODUCT((Lists!$A$2:$A$11=D12)*(LEFT(V12,LEN(Lists!$B$2:$B$11))=Lists!$B$2:$B$11))>0)),"Planned file is not in the folder for this topic",IF(AND(N12<>"",H12<>"",NOT(OR(AND(N12="A",H12="Primary (official)"),AND(OR(N12="B",N12="C"),H12="Secondary"),AND(N12="D",H12="Oral / community")))),"Tier/class mismatch",IF(AND(N12="D",C12<>"P3"),"Tier D is not allowed at launch (set P3)",IF(B12="Source needed",IF(C12="P1","Source needed (launch blocker)",IF(P12="Blocked","Deferred","Source needed")),IF(LEN(Y12)>0,"Incomplete: "&Y12,IF(ISNUMBER(SEARCH("wikipedia",J12)),"Wikipedia is not an accepted source",IF(AND(P12="Verified",OR(Q12="",R12="")),"Verified: add date and verifier",IF(AND(Q12<>"",Q12>TODAY()),"Future verification date",IF(AND(P12="Verified",N12="C",S12=""),"Tier C: add corroboration or EXCEPTION",IF(AND(P12="Verified",N12="D",T12=""),"Tier D: add Verification Lead note",IF(AND(P12="Conflict",U12=""),"Conflict needs a note",IF(W12=0,"Not linked to any planned document","OK"))))))))))))))) | Y12: =IF(A12="","",IF(B12="Source needed","",IF(D12="","topic; ","")&IF(F12="","title; ","")&IF(G12="","type; ","")&IF(H12="","primary/secondary; ","")&IF(I12="","publisher; ","")&IF(J12="","URL/location; ","")&IF(K12="","location type; ","")&IF(AND(K12="Hosted copy",L12=""),"host of copy; ","")&IF(M12="","publication date; ","")&IF(N12="","tier; ","")))
A13: SRC-012 | B13: Source needed | C13: P1 | D13: education | E13: Universities and tertiary institutions in Ekiti | G13: Regulator list | H13: Primary (official) | I13: National Universities Commission (nuc.edu.ng; exact list page to identify) | N13: A | O13: Education | P13: Not started | U13: Volatile: university counts change. News reports describe new federal university legislation for Iyin-Ekiti (2025): confirm against NUC before listing. Also check the state Ministry of Education for polytechnics and colleges. | V13: 06_Education/tertiary-institutions.md | W13: =COUNTIF('First Documents'!$G$2:$G$300,A13) | X13: =IF(A13="","",IF(LEFT(A13,4)<>"SRC-","Bad ID format",IF(COUNTIF($A$2:$A$300,A13)>1,"Duplicate ID",IF(NOT(OR(V13="",SUMPRODUCT((Lists!$A$2:$A$11=D13)*(LEFT(V13,LEN(Lists!$B$2:$B$11))=Lists!$B$2:$B$11))>0)),"Planned file is not in the folder for this topic",IF(AND(N13<>"",H13<>"",NOT(OR(AND(N13="A",H13="Primary (official)"),AND(OR(N13="B",N13="C"),H13="Secondary"),AND(N13="D",H13="Oral / community")))),"Tier/class mismatch",IF(AND(N13="D",C13<>"P3"),"Tier D is not allowed at launch (set P3)",IF(B13="Source needed",IF(C13="P1","Source needed (launch blocker)",IF(P13="Blocked","Deferred","Source needed")),IF(LEN(Y13)>0,"Incomplete: "&Y13,IF(ISNUMBER(SEARCH("wikipedia",J13)),"Wikipedia is not an accepted source",IF(AND(P13="Verified",OR(Q13="",R13="")),"Verified: add date and verifier",IF(AND(Q13<>"",Q13>TODAY()),"Future verification date",IF(AND(P13="Verified",N13="C",S13=""),"Tier C: add corroboration or EXCEPTION",IF(AND(P13="Verified",N13="D",T13=""),"Tier D: add Verification Lead note",IF(AND(P13="Conflict",U13=""),"Conflict needs a note",IF(W13=0,"Not linked to any planned document","OK"))))))))))))))) | Y13: =IF(A13="","",IF(B13="Source needed","",IF(D13="","topic; ","")&IF(F13="","title; ","")&IF(G13="","type; ","")&IF(H13="","primary/secondary; ","")&IF(I13="","publisher; ","")&IF(J13="","URL/location; ","")&IF(K13="","location type; ","")&IF(AND(K13="Hosted copy",L13=""),"host of copy; ","")&IF(M13="","publication date; ","")&IF(N13="","tier; ","")))
A14: SRC-013 | B14: Source needed | C14: P1 | D14: health | E14: Major hospitals and health facilities | G14: Government registry / listing | H14: Primary (official) | I14: Federal Ministry of Health; Ekiti State Ministry of Health (to identify) | N14: A | O14: Research & History | P14: Not started | U14: Locate the official facility registry. Confirm the current status of each facility. | V14: 07_Health/major-facilities.md | W14: =COUNTIF('First Documents'!$G$2:$G$300,A14) | X14: =IF(A14="","",IF(LEFT(A14,4)<>"SRC-","Bad ID format",IF(COUNTIF($A$2:$A$300,A14)>1,"Duplicate ID",IF(NOT(OR(V14="",SUMPRODUCT((Lists!$A$2:$A$11=D14)*(LEFT(V14,LEN(Lists!$B$2:$B$11))=Lists!$B$2:$B$11))>0)),"Planned file is not in the folder for this topic",IF(AND(N14<>"",H14<>"",NOT(OR(AND(N14="A",H14="Primary (official)"),AND(OR(N14="B",N14="C"),H14="Secondary"),AND(N14="D",H14="Oral / community")))),"Tier/class mismatch",IF(AND(N14="D",C14<>"P3"),"Tier D is not allowed at launch (set P3)",IF(B14="Source needed",IF(C14="P1","Source needed (launch blocker)",IF(P14="Blocked","Deferred","Source needed")),IF(LEN(Y14)>0,"Incomplete: "&Y14,IF(ISNUMBER(SEARCH("wikipedia",J14)),"Wikipedia is not an accepted source",IF(AND(P14="Verified",OR(Q14="",R14="")),"Verified: add date and verifier",IF(AND(Q14<>"",Q14>TODAY()),"Future verification date",IF(AND(P14="Verified",N14="C",S14=""),"Tier C: add corroboration or EXCEPTION",IF(AND(P14="Verified",N14="D",T14=""),"Tier D: add Verification Lead note",IF(AND(P14="Conflict",U14=""),"Conflict needs a note",IF(W14=0,"Not linked to any planned document","OK"))))))))))))))) | Y14: =IF(A14="","",IF(B14="Source needed","",IF(D14="","topic; ","")&IF(F14="","title; ","")&IF(G14="","type; ","")&IF(H14="","primary/secondary; ","")&IF(I14="","publisher; ","")&IF(J14="","URL/location; ","")&IF(K14="","location type; ","")&IF(AND(K14="Hosted copy",L14=""),"host of copy; ","")&IF(M14="","publication date; ","")&IF(N14="","tier; ","")))
A15: SRC-014 | B15: Source needed | C15: P1 | D15: history | E15: 30–50 timeline milestones 1996–2026 | G15: Various: register each event's sources separately (SRC-1xx) | I15: Various | N15: C | O15: Research & History | P15: Not started | U15: Each event needs its own source record. Tier C events need two independent sources unless a documented exception applies. Prefer official sources. | V15: 03_Timeline/<year>-<slug>.md | W15: =COUNTIF('First Documents'!$G$2:$G$300,A15) | X15: =IF(A15="","",IF(LEFT(A15,4)<>"SRC-","Bad ID format",IF(COUNTIF($A$2:$A$300,A15)>1,"Duplicate ID",IF(NOT(OR(V15="",SUMPRODUCT((Lists!$A$2:$A$11=D15)*(LEFT(V15,LEN(Lists!$B$2:$B$11))=Lists!$B$2:$B$11))>0)),"Planned file is not in the folder for this topic",IF(AND(N15<>"",H15<>"",NOT(OR(AND(N15="A",H15="Primary (official)"),AND(OR(N15="B",N15="C"),H15="Secondary"),AND(N15="D",H15="Oral / community")))),"Tier/class mismatch",IF(AND(N15="D",C15<>"P3"),"Tier D is not allowed at launch (set P3)",IF(B15="Source needed",IF(C15="P1","Source needed (launch blocker)",IF(P15="Blocked","Deferred","Source needed")),IF(LEN(Y15)>0,"Incomplete: "&Y15,IF(ISNUMBER(SEARCH("wikipedia",J15)),"Wikipedia is not an accepted source",IF(AND(P15="Verified",OR(Q15="",R15="")),"Verified: add date and verifier",IF(AND(Q15<>"",Q15>TODAY()),"Future verification date",IF(AND(P15="Verified",N15="C",S15=""),"Tier C: add corroboration or EXCEPTION",IF(AND(P15="Verified",N15="D",T15=""),"Tier D: add Verification Lead note",IF(AND(P15="Conflict",U15=""),"Conflict needs a note",IF(W15=0,"Not linked to any planned document","OK"))))))))))))))) | Y15: =IF(A15="","",IF(B15="Source needed","",IF(D15="","topic; ","")&IF(F15="","title; ","")&IF(G15="","type; ","")&IF(H15="","primary/secondary; ","")&IF(I15="","publisher; ","")&IF(J15="","URL/location; ","")&IF(K15="","location type; ","")&IF(AND(K15="Hosted copy",L15=""),"host of copy; ","")&IF(M15="","publication date; ","")&IF(N15="","tier; ","")))
A16: SRC-015 | B16: Source needed | C16: P1 | D16: statistics | E16: Education statistics (enrolment, schools, literacy) | G16: Statistical publication | H16: Primary (official) | I16: National Bureau of Statistics; UBEC; State Universal Basic Education Board (to identify) | N16: A | O16: Education | P16: Not started | U16: Record the reference year for every figure. | V16: 09_Statistics/education-and-economy.md | W16: =COUNTIF('First Documents'!$G$2:$G$300,A16) | X16: =IF(A16="","",IF(LEFT(A16,4)<>"SRC-","Bad ID format",IF(COUNTIF($A$2:$A$300,A16)>1,"Duplicate ID",IF(NOT(OR(V16="",SUMPRODUCT((Lists!$A$2:$A$11=D16)*(LEFT(V16,LEN(Lists!$B$2:$B$11))=Lists!$B$2:$B$11))>0)),"Planned file is not in the folder for this topic",IF(AND(N16<>"",H16<>"",NOT(OR(AND(N16="A",H16="Primary (official)"),AND(OR(N16="B",N16="C"),H16="Secondary"),AND(N16="D",H16="Oral / community")))),"Tier/class mismatch",IF(AND(N16="D",C16<>"P3"),"Tier D is not allowed at launch (set P3)",IF(B16="Source needed",IF(C16="P1","Source needed (launch blocker)",IF(P16="Blocked","Deferred","Source needed")),IF(LEN(Y16)>0,"Incomplete: "&Y16,IF(ISNUMBER(SEARCH("wikipedia",J16)),"Wikipedia is not an accepted source",IF(AND(P16="Verified",OR(Q16="",R16="")),"Verified: add date and verifier",IF(AND(Q16<>"",Q16>TODAY()),"Future verification date",IF(AND(P16="Verified",N16="C",S16=""),"Tier C: add corroboration or EXCEPTION",IF(AND(P16="Verified",N16="D",T16=""),"Tier D: add Verification Lead note",IF(AND(P16="Conflict",U16=""),"Conflict needs a note",IF(W16=0,"Not linked to any planned document","OK"))))))))))))))) | Y16: =IF(A16="","",IF(B16="Source needed","",IF(D16="","topic; ","")&IF(F16="","title; ","")&IF(G16="","type; ","")&IF(H16="","primary/secondary; ","")&IF(I16="","publisher; ","")&IF(J16="","URL/location; ","")&IF(K16="","location type; ","")&IF(AND(K16="Hosted copy",L16=""),"host of copy; ","")&IF(M16="","publication date; ","")&IF(N16="","tier; ","")))
A17: SRC-016 | B17: Source needed | C17: P1 | D17: statistics | E17: Economy and poverty statistics | G17: Statistical publication | H17: Primary (official) | I17: National Bureau of Statistics (report to identify) | N17: A | O17: Business & Innovation | P17: Not started | U17: Record the reference year and definitions for every figure. | V17: 09_Statistics/education-and-economy.md | W17: =COUNTIF('First Documents'!$G$2:$G$300,A17) | X17: =IF(A17="","",IF(LEFT(A17,4)<>"SRC-","Bad ID format",IF(COUNTIF($A$2:$A$300,A17)>1,"Duplicate ID",IF(NOT(OR(V17="",SUMPRODUCT((Lists!$A$2:$A$11=D17)*(LEFT(V17,LEN(Lists!$B$2:$B$11))=Lists!$B$2:$B$11))>0)),"Planned file is not in the folder for this topic",IF(AND(N17<>"",H17<>"",NOT(OR(AND(N17="A",H17="Primary (official)"),AND(OR(N17="B",N17="C"),H17="Secondary"),AND(N17="D",H17="Oral / community")))),"Tier/class mismatch",IF(AND(N17="D",C17<>"P3"),"Tier D is not allowed at launch (set P3)",IF(B17="Source needed",IF(C17="P1","Source needed (launch blocker)",IF(P17="Blocked","Deferred","Source needed")),IF(LEN(Y17)>0,"Incomplete: "&Y17,IF(ISNUMBER(SEARCH("wikipedia",J17)),"Wikipedia is not an accepted source",IF(AND(P17="Verified",OR(Q17="",R17="")),"Verified: add date and verifier",IF(AND(Q17<>"",Q17>TODAY()),"Future verification date",IF(AND(P17="Verified",N17="C",S17=""),"Tier C: add corroboration or EXCEPTION",IF(AND(P17="Verified",N17="D",T17=""),"Tier D: add Verification Lead note",IF(AND(P17="Conflict",U17=""),"Conflict needs a note",IF(W17=0,"Not linked to any planned document","OK"))))))))))))))) | Y17: =IF(A17="","",IF(B17="Source needed","",IF(D17="","topic; ","")&IF(F17="","title; ","")&IF(G17="","type; ","")&IF(H17="","primary/secondary; ","")&IF(I17="","publisher; ","")&IF(J17="","URL/location; ","")&IF(K17="","location type; ","")&IF(AND(K17="Hosted copy",L17=""),"host of copy; ","")&IF(M17="","publication date; ","")&IF(N17="","tier; ","")))
A18: SRC-017 | B18: Source needed | C18: P1 | D18: agriculture | E18: Main crops, programmes, output figures | G18: Government report / statistics | H18: Primary (official) | I18: State Ministry of Agriculture; NBS (to identify) | N18: A | O18: Business & Innovation | P18: Not started | U18: Keep programme descriptions separate from output statistics. | V18: 08_Agriculture/overview.md | W18: =COUNTIF('First Documents'!$G$2:$G$300,A18) | X18: =IF(A18="","",IF(LEFT(A18,4)<>"SRC-","Bad ID format",IF(COUNTIF($A$2:$A$300,A18)>1,"Duplicate ID",IF(NOT(OR(V18="",SUMPRODUCT((Lists!$A$2:$A$11=D18)*(LEFT(V18,LEN(Lists!$B$2:$B$11))=Lists!$B$2:$B$11))>0)),"Planned file is not in the folder for this topic",IF(AND(N18<>"",H18<>"",NOT(OR(AND(N18="A",H18="Primary (official)"),AND(OR(N18="B",N18="C"),H18="Secondary"),AND(N18="D",H18="Oral / community")))),"Tier/class mismatch",IF(AND(N18="D",C18<>"P3"),"Tier D is not allowed at launch (set P3)",IF(B18="Source needed",IF(C18="P1","Source needed (launch blocker)",IF(P18="Blocked","Deferred","Source needed")),IF(LEN(Y18)>0,"Incomplete: "&Y18,IF(ISNUMBER(SEARCH("wikipedia",J18)),"Wikipedia is not an accepted source",IF(AND(P18="Verified",OR(Q18="",R18="")),"Verified: add date and verifier",IF(AND(Q18<>"",Q18>TODAY()),"Future verification date",IF(AND(P18="Verified",N18="C",S18=""),"Tier C: add corroboration or EXCEPTION",IF(AND(P18="Verified",N18="D",T18=""),"Tier D: add Verification Lead note",IF(AND(P18="Conflict",U18=""),"Conflict needs a note",IF(W18=0,"Not linked to any planned document","OK"))))))))))))))) | Y18: =IF(A18="","",IF(B18="Source needed","",IF(D18="","topic; ","")&IF(F18="","title; ","")&IF(G18="","type; ","")&IF(H18="","primary/secondary; ","")&IF(I18="","publisher; ","")&IF(J18="","URL/location; ","")&IF(K18="","location type; ","")&IF(AND(K18="Hosted copy",L18=""),"host of copy; ","")&IF(M18="","publication date; ","")&IF(N18="","tier; ","")))
A19: SRC-018 | B19: Source needed | C19: P1 | D19: history | E19: Pre-1996 background (Ekiti kingdoms, Ekitiparapo era) | G19: Academic work | H19: Secondary | I19: University press or academic publisher (to identify) | N19: B | O19: Research & History | P19: Not started | U19: Team decision: a small verified pre-1996 set is included at launch. Keep it separate from the 1996–2026 timeline (folder 01_History/pre-1996/, no 03_Timeline files). Name author, edition and page for each claim. | V19: 01_History/pre-1996/<slug>.md | W19: =COUNTIF('First Documents'!$G$2:$G$300,A19) | X19: =IF(A19="","",IF(LEFT(A19,4)<>"SRC-","Bad ID format",IF(COUNTIF($A$2:$A$300,A19)>1,"Duplicate ID",IF(NOT(OR(V19="",SUMPRODUCT((Lists!$A$2:$A$11=D19)*(LEFT(V19,LEN(Lists!$B$2:$B$11))=Lists!$B$2:$B$11))>0)),"Planned file is not in the folder for this topic",IF(AND(N19<>"",H19<>"",NOT(OR(AND(N19="A",H19="Primary (official)"),AND(OR(N19="B",N19="C"),H19="Secondary"),AND(N19="D",H19="Oral / community")))),"Tier/class mismatch",IF(AND(N19="D",C19<>"P3"),"Tier D is not allowed at launch (set P3)",IF(B19="Source needed",IF(C19="P1","Source needed (launch blocker)",IF(P19="Blocked","Deferred","Source needed")),IF(LEN(Y19)>0,"Incomplete: "&Y19,IF(ISNUMBER(SEARCH("wikipedia",J19)),"Wikipedia is not an accepted source",IF(AND(P19="Verified",OR(Q19="",R19="")),"Verified: add date and verifier",IF(AND(Q19<>"",Q19>TODAY()),"Future verification date",IF(AND(P19="Verified",N19="C",S19=""),"Tier C: add corroboration or EXCEPTION",IF(AND(P19="Verified",N19="D",T19=""),"Tier D: add Verification Lead note",IF(AND(P19="Conflict",U19=""),"Conflict needs a note",IF(W19=0,"Not linked to any planned document","OK"))))))))))))))) | Y19: =IF(A19="","",IF(B19="Source needed","",IF(D19="","topic; ","")&IF(F19="","title; ","")&IF(G19="","type; ","")&IF(H19="","primary/secondary; ","")&IF(I19="","publisher; ","")&IF(J19="","URL/location; ","")&IF(K19="","location type; ","")&IF(AND(K19="Hosted copy",L19=""),"host of copy; ","")&IF(M19="","publication date; ","")&IF(N19="","tier; ","")))
A20: SRC-019 | B20: Source needed | C20: P2 | D20: culture | E20: Festivals, traditions, languages and dialects (published studies) | G20: Academic work | H20: Secondary | I20: To identify | N20: B | O20: Culture & Tourism | P20: Not started | U20: Published scholarship only. Oral accounts go in SRC-026. | V20: 05_Culture/festivals-and-traditions.md | W20: =COUNTIF('First Documents'!$G$2:$G$300,A20) | X20: =IF(A20="","",IF(LEFT(A20,4)<>"SRC-","Bad ID format",IF(COUNTIF($A$2:$A$300,A20)>1,"Duplicate ID",IF(NOT(OR(V20="",SUMPRODUCT((Lists!$A$2:$A$11=D20)*(LEFT(V20,LEN(Lists!$B$2:$B$11))=Lists!$B$2:$B$11))>0)),"Planned file is not in the folder for this topic",IF(AND(N20<>"",H20<>"",NOT(OR(AND(N20="A",H20="Primary (official)"),AND(OR(N20="B",N20="C"),H20="Secondary"),AND(N20="D",H20="Oral / community")))),"Tier/class mismatch",IF(AND(N20="D",C20<>"P3"),"Tier D is not allowed at launch (set P3)",IF(B20="Source needed",IF(C20="P1","Source needed (launch blocker)",IF(P20="Blocked","Deferred","Source needed")),IF(LEN(Y20)>0,"Incomplete: "&Y20,IF(ISNUMBER(SEARCH("wikipedia",J20)),"Wikipedia is not an accepted source",IF(AND(P20="Verified",OR(Q20="",R20="")),"Verified: add date and verifier",IF(AND(Q20<>"",Q20>TODAY()),"Future verification date",IF(AND(P20="Verified",N20="C",S20=""),"Tier C: add corroboration or EXCEPTION",IF(AND(P20="Verified",N20="D",T20=""),"Tier D: add Verification Lead note",IF(AND(P20="Conflict",U20=""),"Conflict needs a note",IF(W20=0,"Not linked to any planned document","OK"))))))))))))))) | Y20: =IF(A20="","",IF(B20="Source needed","",IF(D20="","topic; ","")&IF(F20="","title; ","")&IF(G20="","type; ","")&IF(H20="","primary/secondary; ","")&IF(I20="","publisher; ","")&IF(J20="","URL/location; ","")&IF(K20="","location type; ","")&IF(AND(K20="Hosted copy",L20=""),"host of copy; ","")&IF(M20="","publication date; ","")&IF(N20="","tier; ","")))
A21: SRC-020 | B21: Source needed | C21: P2 | D21: culture | E21: Traditional rulers and the council of traditional rulers | G21: Official record | H21: Primary (official) | I21: State government; council secretariat (to identify) | N21: A | O21: Culture & Tourism | P21: Not started | U21: Titles and lineages are sensitive: verify with the palace or council where possible. Interview accounts are recorded separately under SRC-026. | V21: 05_Culture/traditional-rulers.md | W21: =COUNTIF('First Documents'!$G$2:$G$300,A21) | X21: =IF(A21="","",IF(LEFT(A21,4)<>"SRC-","Bad ID format",IF(COUNTIF($A$2:$A$300,A21)>1,"Duplicate ID",IF(NOT(OR(V21="",SUMPRODUCT((Lists!$A$2:$A$11=D21)*(LEFT(V21,LEN(Lists!$B$2:$B$11))=Lists!$B$2:$B$11))>0)),"Planned file is not in the folder for this topic",IF(AND(N21<>"",H21<>"",NOT(OR(AND(N21="A",H21="Primary (official)"),AND(OR(N21="B",N21="C"),H21="Secondary"),AND(N21="D",H21="Oral / community")))),"Tier/class mismatch",IF(AND(N21="D",C21<>"P3"),"Tier D is not allowed at launch (set P3)",IF(B21="Source needed",IF(C21="P1","Source needed (launch blocker)",IF(P21="Blocked","Deferred","Source needed")),IF(LEN(Y21)>0,"Incomplete: "&Y21,IF(ISNUMBER(SEARCH("wikipedia",J21)),"Wikipedia is not an accepted source",IF(AND(P21="Verified",OR(Q21="",R21="")),"Verified: add date and verifier",IF(AND(Q21<>"",Q21>TODAY()),"Future verification date",IF(AND(P21="Verified",N21="C",S21=""),"Tier C: add corroboration or EXCEPTION",IF(AND(P21="Verified",N21="D",T21=""),"Tier D: add Verification Lead note",IF(AND(P21="Conflict",U21=""),"Conflict needs a note",IF(W21=0,"Not linked to any planned document","OK"))))))))))))))) | Y21: =IF(A21="","",IF(B21="Source needed","",IF(D21="","topic; ","")&IF(F21="","title; ","")&IF(G21="","type; ","")&IF(H21="","primary/secondary; ","")&IF(I21="","publisher; ","")&IF(J21="","URL/location; ","")&IF(K21="","location type; ","")&IF(AND(K21="Hosted copy",L21=""),"host of copy; ","")&IF(M21="","publication date; ","")&IF(N21="","tier; ","")))
A22: SRC-021 | B22: Source needed | C22: P2 | D22: government | E22: State laws, budgets, ministries and agencies | G22: Government documents | H22: Primary (official) | I22: Government of Ekiti State; State House of Assembly (to identify) | N22: A | O22: Verification & Editorial | P22: Not started | U22: Record the fiscal year of every budget figure. | V22: 01_History/government/laws-budgets-mdas.md | W22: =COUNTIF('First Documents'!$G$2:$G$300,A22) | X22: =IF(A22="","",IF(LEFT(A22,4)<>"SRC-","Bad ID format",IF(COUNTIF($A$2:$A$300,A22)>1,"Duplicate ID",IF(NOT(OR(V22="",SUMPRODUCT((Lists!$A$2:$A$11=D22)*(LEFT(V22,LEN(Lists!$B$2:$B$11))=Lists!$B$2:$B$11))>0)),"Planned file is not in the folder for this topic",IF(AND(N22<>"",H22<>"",NOT(OR(AND(N22="A",H22="Primary (official)"),AND(OR(N22="B",N22="C"),H22="Secondary"),AND(N22="D",H22="Oral / community")))),"Tier/class mismatch",IF(AND(N22="D",C22<>"P3"),"Tier D is not allowed at launch (set P3)",IF(B22="Source needed",IF(C22="P1","Source needed (launch blocker)",IF(P22="Blocked","Deferred","Source needed")),IF(LEN(Y22)>0,"Incomplete: "&Y22,IF(ISNUMBER(SEARCH("wikipedia",J22)),"Wikipedia is not an accepted source",IF(AND(P22="Verified",OR(Q22="",R22="")),"Verified: add date and verifier",IF(AND(Q22<>"",Q22>TODAY()),"Future verification date",IF(AND(P22="Verified",N22="C",S22=""),"Tier C: add corroboration or EXCEPTION",IF(AND(P22="Verified",N22="D",T22=""),"Tier D: add Verification Lead note",IF(AND(P22="Conflict",U22=""),"Conflict needs a note",IF(W22=0,"Not linked to any planned document","OK"))))))))))))))) | Y22: =IF(A22="","",IF(B22="Source needed","",IF(D22="","topic; ","")&IF(F22="","title; ","")&IF(G22="","type; ","")&IF(H22="","primary/secondary; ","")&IF(I22="","publisher; ","")&IF(J22="","URL/location; ","")&IF(K22="","location type; ","")&IF(AND(K22="Hosted copy",L22=""),"host of copy; ","")&IF(M22="","publication date; ","")&IF(N22="","tier; ","")))
A23: SRC-022 | B23: Source needed | C23: P2 | D23: government | E23: Infrastructure projects (roads, airport, water, power) | G23: Mixed | H23: Secondary | I23: Ministry of Works; news (to identify) | N23: C | O23: Engineering | P23: Not started | U23: Separate completed, ongoing and announced projects. Prefer official sources. | V23: 01_History/government/infrastructure.md | W23: =COUNTIF('First Documents'!$G$2:$G$300,A23) | X23: =IF(A23="","",IF(LEFT(A23,4)<>"SRC-","Bad ID format",IF(COUNTIF($A$2:$A$300,A23)>1,"Duplicate ID",IF(NOT(OR(V23="",SUMPRODUCT((Lists!$A$2:$A$11=D23)*(LEFT(V23,LEN(Lists!$B$2:$B$11))=Lists!$B$2:$B$11))>0)),"Planned file is not in the folder for this topic",IF(AND(N23<>"",H23<>"",NOT(OR(AND(N23="A",H23="Primary (official)"),AND(OR(N23="B",N23="C"),H23="Secondary"),AND(N23="D",H23="Oral / community")))),"Tier/class mismatch",IF(AND(N23="D",C23<>"P3"),"Tier D is not allowed at launch (set P3)",IF(B23="Source needed",IF(C23="P1","Source needed (launch blocker)",IF(P23="Blocked","Deferred","Source needed")),IF(LEN(Y23)>0,"Incomplete: "&Y23,IF(ISNUMBER(SEARCH("wikipedia",J23)),"Wikipedia is not an accepted source",IF(AND(P23="Verified",OR(Q23="",R23="")),"Verified: add date and verifier",IF(AND(Q23<>"",Q23>TODAY()),"Future verification date",IF(AND(P23="Verified",N23="C",S23=""),"Tier C: add corroboration or EXCEPTION",IF(AND(P23="Verified",N23="D",T23=""),"Tier D: add Verification Lead note",IF(AND(P23="Conflict",U23=""),"Conflict needs a note",IF(W23=0,"Not linked to any planned document","OK"))))))))))))))) | Y23: =IF(A23="","",IF(B23="Source needed","",IF(D23="","topic; ","")&IF(F23="","title; ","")&IF(G23="","type; ","")&IF(H23="","primary/secondary; ","")&IF(I23="","publisher; ","")&IF(J23="","URL/location; ","")&IF(K23="","location type; ","")&IF(AND(K23="Hosted copy",L23=""),"host of copy; ","")&IF(M23="","publication date; ","")&IF(N23="","tier; ","")))
A24: SRC-023 | B24: Source needed | C24: P2 | D24: education | E24: Primary and secondary school lists by LGA | G24: Government listing | H24: Primary (official) | I24: State Ministry of Education; SUBEB (to identify) | N24: A | O24: Education | P24: Not started | U24: Large dataset: sample first. | V24: 06_Education/schools.md | W24: =COUNTIF('First Documents'!$G$2:$G$300,A24) | X24: =IF(A24="","",IF(LEFT(A24,4)<>"SRC-","Bad ID format",IF(COUNTIF($A$2:$A$300,A24)>1,"Duplicate ID",IF(NOT(OR(V24="",SUMPRODUCT((Lists!$A$2:$A$11=D24)*(LEFT(V24,LEN(Lists!$B$2:$B$11))=Lists!$B$2:$B$11))>0)),"Planned file is not in the folder for this topic",IF(AND(N24<>"",H24<>"",NOT(OR(AND(N24="A",H24="Primary (official)"),AND(OR(N24="B",N24="C"),H24="Secondary"),AND(N24="D",H24="Oral / community")))),"Tier/class mismatch",IF(AND(N24="D",C24<>"P3"),"Tier D is not allowed at launch (set P3)",IF(B24="Source needed",IF(C24="P1","Source needed (launch blocker)",IF(P24="Blocked","Deferred","Source needed")),IF(LEN(Y24)>0,"Incomplete: "&Y24,IF(ISNUMBER(SEARCH("wikipedia",J24)),"Wikipedia is not an accepted source",IF(AND(P24="Verified",OR(Q24="",R24="")),"Verified: add date and verifier",IF(AND(Q24<>"",Q24>TODAY()),"Future verification date",IF(AND(P24="Verified",N24="C",S24=""),"Tier C: add corroboration or EXCEPTION",IF(AND(P24="Verified",N24="D",T24=""),"Tier D: add Verification Lead note",IF(AND(P24="Conflict",U24=""),"Conflict needs a note",IF(W24=0,"Not linked to any planned document","OK"))))))))))))))) | Y24: =IF(A24="","",IF(B24="Source needed","",IF(D24="","topic; ","")&IF(F24="","title; ","")&IF(G24="","type; ","")&IF(H24="","primary/secondary; ","")&IF(I24="","publisher; ","")&IF(J24="","URL/location; ","")&IF(K24="","location type; ","")&IF(AND(K24="Hosted copy",L24=""),"host of copy; ","")&IF(M24="","publication date; ","")&IF(N24="","tier; ","")))
A25: SRC-024 | B25: Source needed | C25: P3 | D25: culture | E25: Sports history and achievements | G25: News / official records | H25: Secondary | I25: To identify | N25: C | O25: Media & Content | P25: Not started | U25: After launch. | V25: 05_Culture/sports.md | W25: =COUNTIF('First Documents'!$G$2:$G$300,A25) | X25: =IF(A25="","",IF(LEFT(A25,4)<>"SRC-","Bad ID format",IF(COUNTIF($A$2:$A$300,A25)>1,"Duplicate ID",IF(NOT(OR(V25="",SUMPRODUCT((Lists!$A$2:$A$11=D25)*(LEFT(V25,LEN(Lists!$B$2:$B$11))=Lists!$B$2:$B$11))>0)),"Planned file is not in the folder for this topic",IF(AND(N25<>"",H25<>"",NOT(OR(AND(N25="A",H25="Primary (official)"),AND(OR(N25="B",N25="C"),H25="Secondary"),AND(N25="D",H25="Oral / community")))),"Tier/class mismatch",IF(AND(N25="D",C25<>"P3"),"Tier D is not allowed at launch (set P3)",IF(B25="Source needed",IF(C25="P1","Source needed (launch blocker)",IF(P25="Blocked","Deferred","Source needed")),IF(LEN(Y25)>0,"Incomplete: "&Y25,IF(ISNUMBER(SEARCH("wikipedia",J25)),"Wikipedia is not an accepted source",IF(AND(P25="Verified",OR(Q25="",R25="")),"Verified: add date and verifier",IF(AND(Q25<>"",Q25>TODAY()),"Future verification date",IF(AND(P25="Verified",N25="C",S25=""),"Tier C: add corroboration or EXCEPTION",IF(AND(P25="Verified",N25="D",T25=""),"Tier D: add Verification Lead note",IF(AND(P25="Conflict",U25=""),"Conflict needs a note",IF(W25=0,"Not linked to any planned document","OK"))))))))))))))) | Y25: =IF(A25="","",IF(B25="Source needed","",IF(D25="","topic; ","")&IF(F25="","title; ","")&IF(G25="","type; ","")&IF(H25="","primary/secondary; ","")&IF(I25="","publisher; ","")&IF(J25="","URL/location; ","")&IF(K25="","location type; ","")&IF(AND(K25="Hosted copy",L25=""),"host of copy; ","")&IF(M25="","publication date; ","")&IF(N25="","tier; ","")))
A26: SRC-025 | B26: Source needed | C26: P3 | D26: tourism | E26: Extended sites, hotels, festival calendar | G26: Mixed | H26: Secondary | I26: To identify | N26: B | O26: Culture & Tourism | P26: Not started | U26: After launch. | V26: 04_Tourism/extended-sites.md | W26: =COUNTIF('First Documents'!$G$2:$G$300,A26) | X26: =IF(A26="","",IF(LEFT(A26,4)<>"SRC-","Bad ID format",IF(COUNTIF($A$2:$A$300,A26)>1,"Duplicate ID",IF(NOT(OR(V26="",SUMPRODUCT((Lists!$A$2:$A$11=D26)*(LEFT(V26,LEN(Lists!$B$2:$B$11))=Lists!$B$2:$B$11))>0)),"Planned file is not in the folder for this topic",IF(AND(N26<>"",H26<>"",NOT(OR(AND(N26="A",H26="Primary (official)"),AND(OR(N26="B",N26="C"),H26="Secondary"),AND(N26="D",H26="Oral / community")))),"Tier/class mismatch",IF(AND(N26="D",C26<>"P3"),"Tier D is not allowed at launch (set P3)",IF(B26="Source needed",IF(C26="P1","Source needed (launch blocker)",IF(P26="Blocked","Deferred","Source needed")),IF(LEN(Y26)>0,"Incomplete: "&Y26,IF(ISNUMBER(SEARCH("wikipedia",J26)),"Wikipedia is not an accepted source",IF(AND(P26="Verified",OR(Q26="",R26="")),"Verified: add date and verifier",IF(AND(Q26<>"",Q26>TODAY()),"Future verification date",IF(AND(P26="Verified",N26="C",S26=""),"Tier C: add corroboration or EXCEPTION",IF(AND(P26="Verified",N26="D",T26=""),"Tier D: add Verification Lead note",IF(AND(P26="Conflict",U26=""),"Conflict needs a note",IF(W26=0,"Not linked to any planned document","OK"))))))))))))))) | Y26: =IF(A26="","",IF(B26="Source needed","",IF(D26="","topic; ","")&IF(F26="","title; ","")&IF(G26="","type; ","")&IF(H26="","primary/secondary; ","")&IF(I26="","publisher; ","")&IF(J26="","URL/location; ","")&IF(K26="","location type; ","")&IF(AND(K26="Hosted copy",L26=""),"host of copy; ","")&IF(M26="","publication date; ","")&IF(N26="","tier; ","")))
A27: SRC-026 | B27: Source needed | C27: P3 | D27: culture | E27: Oral and community accounts (elders, palace records, local historians) | G27: Interview / community account | H27: Oral / community | I27: To identify | N27: D | O27: Culture & Tourism | P27: Blocked | U27: DEFERRED by team decision: no Tier D material in the launch KB. Revisit in a later phase once the verification and attribution workflow is mature; each item will then need Verification Lead sign-off and a written note. | V27: 05_Culture/oral-community-accounts.md | W27: =COUNTIF('First Documents'!$G$2:$G$300,A27) | X27: =IF(A27="","",IF(LEFT(A27,4)<>"SRC-","Bad ID format",IF(COUNTIF($A$2:$A$300,A27)>1,"Duplicate ID",IF(NOT(OR(V27="",SUMPRODUCT((Lists!$A$2:$A$11=D27)*(LEFT(V27,LEN(Lists!$B$2:$B$11))=Lists!$B$2:$B$11))>0)),"Planned file is not in the folder for this topic",IF(AND(N27<>"",H27<>"",NOT(OR(AND(N27="A",H27="Primary (official)"),AND(OR(N27="B",N27="C"),H27="Secondary"),AND(N27="D",H27="Oral / community")))),"Tier/class mismatch",IF(AND(N27="D",C27<>"P3"),"Tier D is not allowed at launch (set P3)",IF(B27="Source needed",IF(C27="P1","Source needed (launch blocker)",IF(P27="Blocked","Deferred","Source needed")),IF(LEN(Y27)>0,"Incomplete: "&Y27,IF(ISNUMBER(SEARCH("wikipedia",J27)),"Wikipedia is not an accepted source",IF(AND(P27="Verified",OR(Q27="",R27="")),"Verified: add date and verifier",IF(AND(Q27<>"",Q27>TODAY()),"Future verification date",IF(AND(P27="Verified",N27="C",S27=""),"Tier C: add corroboration or EXCEPTION",IF(AND(P27="Verified",N27="D",T27=""),"Tier D: add Verification Lead note",IF(AND(P27="Conflict",U27=""),"Conflict needs a note",IF(W27=0,"Not linked to any planned document","OK"))))))))))))))) | Y27: =IF(A27="","",IF(B27="Source needed","",IF(D27="","topic; ","")&IF(F27="","title; ","")&IF(G27="","type; ","")&IF(H27="","primary/secondary; ","")&IF(I27="","publisher; ","")&IF(J27="","URL/location; ","")&IF(K27="","location type; ","")&IF(AND(K27="Hosted copy",L27=""),"host of copy; ","")&IF(M27="","publication date; ","")&IF(N27="","tier; ","")))
A28: SRC-027 | B28: Source needed | C28: P1 | D28: government | E28: Election declarations for elected governors | G28: Election result declaration | H28: Primary (official) | I28: Independent National Electoral Commission (INEC) | N28: A | O28: Research & History | P28: Not started | U28: Election outcomes: use the INEC declaration. Where a court changed an outcome, register the judgment as its own source. | V28: 01_History/government/governors-and-administrators.md | W28: =COUNTIF('First Documents'!$G$2:$G$300,A28) | X28: =IF(A28="","",IF(LEFT(A28,4)<>"SRC-","Bad ID format",IF(COUNTIF($A$2:$A$300,A28)>1,"Duplicate ID",IF(NOT(OR(V28="",SUMPRODUCT((Lists!$A$2:$A$11=D28)*(LEFT(V28,LEN(Lists!$B$2:$B$11))=Lists!$B$2:$B$11))>0)),"Planned file is not in the folder for this topic",IF(AND(N28<>"",H28<>"",NOT(OR(AND(N28="A",H28="Primary (official)"),AND(OR(N28="B",N28="C"),H28="Secondary"),AND(N28="D",H28="Oral / community")))),"Tier/class mismatch",IF(AND(N28="D",C28<>"P3"),"Tier D is not allowed at launch (set P3)",IF(B28="Source needed",IF(C28="P1","Source needed (launch blocker)",IF(P28="Blocked","Deferred","Source needed")),IF(LEN(Y28)>0,"Incomplete: "&Y28,IF(ISNUMBER(SEARCH("wikipedia",J28)),"Wikipedia is not an accepted source",IF(AND(P28="Verified",OR(Q28="",R28="")),"Verified: add date and verifier",IF(AND(Q28<>"",Q28>TODAY()),"Future verification date",IF(AND(P28="Verified",N28="C",S28=""),"Tier C: add corroboration or EXCEPTION",IF(AND(P28="Verified",N28="D",T28=""),"Tier D: add Verification Lead note",IF(AND(P28="Conflict",U28=""),"Conflict needs a note",IF(W28=0,"Not linked to any planned document","OK"))))))))))))))) | Y28: =IF(A28="","",IF(B28="Source needed","",IF(D28="","topic; ","")&IF(F28="","title; ","")&IF(G28="","type; ","")&IF(H28="","primary/secondary; ","")&IF(I28="","publisher; ","")&IF(J28="","URL/location; ","")&IF(K28="","location type; ","")&IF(AND(K28="Hosted copy",L28=""),"host of copy; ","")&IF(M28="","publication date; ","")&IF(N28="","tier; ","")))
A301: SRC-028 | B301: Identified | C301: P1 | D301: lgas | E301: LGA data: Ekiti State Government Local Government and LCDAs directory | F301: Ekiti State Government Local Government and LCDAs directory | G301: Government website page | H301: Primary (official) | I301: Government of Ekiti State | J301: https://www.ekitistate.gov.ng/about-ekiti/local-government | K301: Original | M301: Not stated | N301: A | O301: Geospatial | P301: Not started | U301: imported from Member 5's LGA dataset (ekiti_lgas.json) | V301: 02_LGAs/lga-*.md
A302: SRC-029 | B302: Identified | C302: P1 | D302: lgas | E302: LGA data: secondary geographic coordinate reference | F302: secondary geographic coordinate reference | G302: secondary geographic database | H302: Secondary | I302: Third-party geographic reference site | J302: https://www.latlong.net/place/ado-ekiti-nigeria-24847.html | K302: Original | M302: Not stated | N302: C | O302: Geospatial | P302: Not started | U302: imported from Member 5's LGA dataset (ekiti_lgas.json) | V302: 02_LGAs/lga-*.md
A303: SRC-030 | B303: Identified | C303: P1 | D303: lgas | E303: LGA data: secondary geographic coordinate reference | F303: secondary geographic coordinate reference | G303: secondary geographic database | H303: Secondary | I303: Third-party geographic reference site | J303: https://www.geodatos.net/en/coordinates/nigeria/efon-alaaye | K303: Original | M303: Not stated | N303: C | O303: Geospatial | P303: Not started | U303: imported from Member 5's LGA dataset (ekiti_lgas.json) | V303: 02_LGAs/lga-*.md
A304: SRC-031 | B304: Identified | C304: P1 | D304: lgas | E304: LGA data: secondary geographic coordinate reference | F304: secondary geographic coordinate reference | G304: secondary geographic database | H304: Secondary | I304: Third-party geographic reference site | J304: https://www.mindat.org/feature-2325727.html | K304: Original | M304: Not stated | N304: C | O304: Geospatial | P304: Not started | U304: imported from Member 5's LGA dataset (ekiti_lgas.json) | V304: 02_LGAs/lga-*.md
